<?xml version="1.0"?>

<robot xmlns:xacro="http://www.ros.org/wiki/xacro">
<property name="M_PI" value="3.1415926535897931" />
  <xacro:macro name="finger1">
  
       <link name="bhand_link0">
        <inertial>
            <mass value="20" />
            <origin xyz="0.0 0.0 0.0" rpy="0 0 0" />
            <inertia  ixx="1.0" ixy="0.0"  ixz="0.0"  iyy="1.0"  iyz="0.0"  izz="1.0" />
        </inertial>
        <visual>
            <origin xyz="0.0 0.0 0.0" rpy="0 0 0" />
            <geometry name="bhand_link0_visual">
                <mesh filename="package://iri_bhand_description/mesh/bh_link1.stl" scale="1.0 1.0 1.0" />
            </geometry>
            <material name="Grey" >
                <color rgba="0.75 0.75 0.75 1.0"/>
            </material>
        </visual>
        <collision>
            <origin xyz="0.0 0.0 0.0" rpy="0 0 0"/>
            <geometry name="bhand_link0_collision">
               <mesh filename="package://iri_bhand_description/mesh/bh_link1.stl" scale="1.0 1.0 1.0" />
            </geometry>
            <contact_coefficients kd="1.0" kp="1000.0" mu="0"/>
        </collision>
    </link>
       <joint name="j1_joint" type="revolute">
        <parent link="bhand_link0"/>
        <child link="bhand_link1"/>
        <origin xyz="0.0 0.0 0.0" rpy="0 -${M_PI/2} -${M_PI/2}" />
        <axis xyz="0 0 1" />
        <limit lower="-0.9" upper="2.8" effort="35" velocity="2.0"/>
        <dynamics damping="100"/>
       </joint>
      <link name="bhand_link1">
        <inertial>
            <mass value="20" />
            <origin xyz="0.0 0.0 0.0" rpy="0 0 0" />
            <inertia  ixx="1.0" ixy="0.0"  ixz="0.0"  iyy="1.0"  iyz="0.0"  izz="1.0" />
        </inertial>
        <visual>
            <origin xyz="0.0 0.05 0.0" rpy="0 0 0" />
            <geometry name="bhand_link1_visual">
                <mesh filename="package://iri_bhand_description/mesh/bh_link2.stl" scale="1.0 1.0 1.0" />
            </geometry>
            <material name="Grey" >
                <color rgba="0.75 0.75 0.75 1.0"/>
            </material>
        </visual>
        <collision>
            <origin xyz="0.0 0.0 0.0" rpy="0 0 0"/>
            <geometry name="bhand_link1_collision">
               <mesh filename="package://iri_bhand_description/mesh/bh_link2.stl" scale="1.0 1.0 1.0" />
            </geometry>
            <contact_coefficients kd="1.0" kp="1000.0" mu="0"/>
        </collision>
    </link>

  </xacro:macro>

</robot>
