<?xml version="1.0" ?>
<!-- =================================================================================== -->
<!-- |    This document was autogenerated by xacro from wam.urdf.xacro                 | -->
<!-- |    EDITING THIS FILE BY HAND IS NOT RECOMMENDED                                 | -->
<!-- =================================================================================== -->
<robot name="iri_wam" xmlns:controller="http://playerstage.sourceforge.net/gazebo/xmlschema/#controller" xmlns:interface="http://playerstage.sourceforge.net/gazebo/xmlschema/#interface" xmlns:sensor="http://playerstage.sourceforge.net/gazebo/xmlschema/#sensor" xmlns:xacro="http://ros.org/wiki/xacro">
  <!-- Constants -->
  <!-- Includes -->
  <!-- MACROS -->
  <!-- LINKS   -->
  <link name="wambase">
    <inertial>
      <origin rpy="0 0 0" xyz="0 0 0"/>
      <mass value="1"/>
      <inertia ixx="100" ixy="0" ixz="0" iyy="100" iyz="0" izz="100"/>
    </inertial>
    <visual>
      <origin rpy="0 0 0" xyz="0 0 0"/>
      <geometry name="wambase-geom">
        <mesh filename="package://iri_wam_description/mesh/wambase.stl"/>
      </geometry>
      <material name="wambase-mat">
        <color rgba="0.75 0.75 0.75 1.0"/>
      </material>
    </visual>
    <collision>
      <origin rpy="0 0 0" xyz="0 0 0"/>
      <geometry name="wambase-geom">
        <mesh filename="package://iri_wam_description/mesh/wambase.stl"/>
      </geometry>
      <contact_coefficients kd="1.0" kp="1000.0" mu="0"/>
    </collision>
  </link>
  <link name="wam_fk/wam0">
    <inertial>
      <origin rpy="0 0 0" xyz="0 0 0"/>
      <mass value="0.1"/>
      <inertia ixx="100" ixy="0" ixz="0" iyy="100" iyz="0" izz="100"/>
    </inertial>
    <!--
    <visual>
      <origin rpy="0 0 0" xyz="0 0 0"/>
      <geometry name="wam0-geom">
        <mesh filename="package://iri_wam_description/mesh/wam0.stl"/>
      </geometry>
      <material name="wam0-mat">
        <color rgba="0.75 0.75 0.75 1.0"/>
      </material>
    </visual>
-->
    <!--    <collision>
      <origin rpy="0 0 0" xyz="0 0 0"/>
      <geometry name="wam0-geom">
        <mesh filename="package://iri_wam_description/mesh/wam0.stl"/>
      </geometry>
      <contact_coefficients kd="1.0" kp="1000.0" mu="0"/>
    </collision>
-->
  </link>
  <link name="wam_fk/wam1">
    <inertial>
      <origin rpy="0 0 0" xyz="0 0 0"/>
      <mass value="0.1"/>
      <inertia ixx="100" ixy="0" ixz="0" iyy="100" iyz="0" izz="100"/>
    </inertial>
    <visual>
      <origin rpy="0 0 0" xyz="0 0 0"/>
      <geometry name="wam1-geom">
        <mesh filename="package://iri_wam_description/mesh/wam1.stl"/>
      </geometry>
      <material name="wam1-mat">
        <color rgba="0.75 0.75 0.75 1.0"/>
      </material>
    </visual>
    <collision>
      <origin rpy="0 0 0" xyz="0 0 0"/>
      <geometry name="wam1-geom">
        <mesh filename="package://iri_wam_description/mesh/wam1.stl"/>
      </geometry>
      <contact_coefficients kd="1.0" kp="1000.0" mu="0"/>
    </collision>
  </link>
  <link name="wam_fk/wam2">
    <inertial>
      <origin rpy="0 0 0" xyz="0 0 0"/>
      <mass value="0.1"/>
      <inertia ixx="100" ixy="0" ixz="0" iyy="100" iyz="0" izz="100"/>
    </inertial>
    <visual>
      <origin rpy="0 0 0" xyz="0 0 0"/>
      <geometry name="wam2-geom">
        <mesh filename="package://iri_wam_description/mesh/wam2.stl"/>
      </geometry>
      <material name="wam2-mat">
        <color rgba="0.75 0.75 0.75 1.0"/>
      </material>
    </visual>
    <collision>
      <origin rpy="0 0 0" xyz="0 0 0"/>
      <geometry name="wam2-geom">
        <mesh filename="package://iri_wam_description/mesh/wam2.stl"/>
      </geometry>
      <contact_coefficients kd="1.0" kp="1000.0" mu="0"/>
    </collision>
  </link>
  <!--
  <xacro:Link name="wam3" xyz="-0.045 0.55 0" rpy="${pi/2} 0 0" mass="0.1" prefix="wam_fk/"/>
  <xacro:Link name="wam4" xyz="0.045 0 0" rpy="-${pi/2} 0 0" mass="0.1" prefix="wam_fk/"/>
  <xacro:Link name="wam5" xyz="0 0 0" rpy="${pi/2} 0 0" mass="0.1" prefix="wam_fk/"/>
  <xacro:Link name="wam6" xyz="0 0 0" rpy="-${pi/2} 0 0" mass="0.1" prefix="wam_fk/"/>
  <xacro:Link name="wam7" xyz="0 0 -0.06" rpy="0 0 0" mass="0.1" prefix="wam_fk/"/> 
-->
  <!-- JOINTS  -->
  <joint name="j0" type="fixed">
    <parent link="wambase"/>
    <child link="wam_fk/wam0"/>
    <origin rpy="0 0 0" xyz="0 0 0"/>
    <limit effort="0.0" lower="0.0" upper="0.0" velocity="0.0"/>
    <axis xyz="0 0 0"/>
  </joint>
  <joint name="j1" type="revolute">
    <parent link="wam_fk/wam0"/>
    <child link="wam_fk/wam1"/>
    <origin rpy="-1.57080 0 0" xyz="0 0 0"/>
    <limit effort="30" lower="-2.6" upper="2.6" velocity="2"/>
    <axis xyz="0 -1 0"/>
  </joint>
  <joint name="j2" type="revolute">
    <parent link="wam_fk/wam1"/>
    <child link="wam_fk/wam2"/>
    <origin rpy="1.57080 0 0" xyz="0 0 0"/>
    <limit effort="30" lower="-2.0" upper="2.0" velocity="2"/>
    <axis xyz="0 1 0"/>
  </joint>
  <!--
  <xacro:Joint name="j3" type="revolute" xyz="0.045 0 0.55" rpy="-${pi/2} 0 0" upperLim="+2.8" lowerLim="-2.8" effort="30" velocity="2" axis="0 -1 0" parent="wam_fk/wam2" child="wam_fk/wam3" />
  <xacro:Joint name="j4" type="revolute" xyz="-0.045 0 0" rpy="${pi/2} 0 0" upperLim="+3.1" lowerLim="-0.9" effort="30" velocity="2" axis="0 0 1" parent="wam_fk/wam3" child="wam_fk/wam4" />
  <xacro:Joint name="j5" type="revolute" xyz="0 0 0.3" rpy="-${pi/2} 0 0" upperLim="+1.3" lowerLim="-4.8" effort="30" velocity="2" axis="0 0 1" parent="wam_fk/wam4" child="wam_fk/wam5" />
  <xacro:Joint name="j6" type="revolute" xyz="0 0 0" rpy="${pi/2} 0 0" upperLim="+1.6" lowerLim="-1.6" effort="30" velocity="2" axis="0 0 1" parent="wam_fk/wam5" child="wam_fk/wam6" />
  <xacro:Joint name="j7" type="revolute" xyz="0 0 0.06" rpy="0 0 0" upperLim="+2.2" lowerLim="-2.2" effort="30" velocity="2" axis="0 0 1" parent="wam_fk/wam6" child="wam_fk/wam7" />
-->
  <!-- Transmission -->
  <transmission name="linkb_link0_trans" type="pr2_mechanism_model/SimpleTransmission">
    <actuator name="linkb_link0_motor"/>
    <joint name="j0"/>
    <mechanicalReduction>1</mechanicalReduction>
    <motorTorqueConstant>1</motorTorqueConstant>
    <!--  <pulsesPerRevolution>90000</pulsesPerRevolution>-->
  </transmission>
  <transmission name="link0_link1_trans" type="pr2_mechanism_model/SimpleTransmission">
    <actuator name="link0_link1_motor"/>
    <joint name="j1"/>
    <mechanicalReduction>1</mechanicalReduction>
    <motorTorqueConstant>1</motorTorqueConstant>
    <!--  <pulsesPerRevolution>90000</pulsesPerRevolution>-->
  </transmission>
  <transmission name="link1_link2_trans" type="pr2_mechanism_model/SimpleTransmission">
    <actuator name="link1_link2_motor"/>
    <joint name="j2"/>
    <mechanicalReduction>1</mechanicalReduction>
    <motorTorqueConstant>1</motorTorqueConstant>
    <!--  <pulsesPerRevolution>90000</pulsesPerRevolution>-->
  </transmission>
  <!--
  <xacro:Transmission name="link2_link3" jointName="j3" reduction="1" torque="1"/>
  <xacro:Transmission name="link3_link4" jointName="j4" reduction="1" torque="1"/>
  <xacro:Transmission name="link4_link5" jointName="j5" reduction="1" torque="1"/>
  <xacro:Transmission name="link5_link6" jointName="j6" reduction="1" torque="1"/>
  <xacro:Transmission name="link6_link7" jointName="j7" reduction="1" torque="1"/>
-->
  <!-- PLUGINS -->
  <!--  <include filename="$(find iri_wam_gazebo)/urdf/iri_wam.gazebo.xacro" /> -->
</robot>

