<?xml version="1.0" ?>
<!-- =================================================================================== -->
<!-- |    This document was autogenerated by xacro from /home/irojas/ros/iri-ros-pkg/iri_wam/iri_wam_description/xacro/wam_sim_with_inertial.urdf.xacro | -->
<!-- |    EDITING THIS FILE BY HAND IS NOT RECOMMENDED                                 | -->
<!-- =================================================================================== -->
<robot name="iri_wam" xmlns:controller="http://playerstage.sourceforge.net/gazebo/xmlschema/#controller" xmlns:interface="http://playerstage.sourceforge.net/gazebo/xmlschema/#interface" xmlns:sensor="http://playerstage.sourceforge.net/gazebo/xmlschema/#sensor" xmlns:xacro="http://ros.org/wiki/xacro">
  <!-- Constants -->
  <!-- Includes -->
  <!-- MACROS -->
  <!-- LINKS   -->
  <link name="wambase">
    <inertial>
      <origin rpy="0 0 0" xyz="0 0 0"/>
      <mass value="1000"/>
      <inertia ixx="100" ixy="0" ixz="0" iyy="100" iyz="0" izz="100"/>
    </inertial>
    <visual>
      <origin rpy="0 0 0" xyz="0 0 0"/>
      <geometry name="wambase-geom">
        <mesh filename="package://iri_wam_description/mesh/wambase.stl"/>
      </geometry>
      <material name="wambase-mat">
        <color rgba="0.75 0.75 0.75 1.0"/>
      </material>
    </visual>
    <collision>
      <origin rpy="0 0 0" xyz="0 0 0"/>
      <geometry name="wambase-geom">
        <mesh filename="package://iri_wam_description/mesh/wambase.stl"/>
      </geometry>
      <contact_coefficients kd="1.0" kp="1000.0" mu="0"/>
    </collision>
  </link>
  <!-- TODO: Try to add wam0 virtual Link and its corresponding joint since it is how it is defined on the real kinematics
           Not sure if this is possible -->
  <link name="wam_fk/wam1">
    <inertial>
      <origin rpy="0 0 0" xyz="0.00035060 0.13268 0.00062860"/>
      <mass value="8.3936"/>
      <inertia ixx="0.24292" ixy="0.00063655" ixz="-9.3e-06" iyy="0.092037" iyz="-0.00026265" izz="0.20705"/>
    </inertial>
    <visual>
      <origin rpy="0 0 0" xyz="0 0 0"/>
      <geometry name="wam1-geom">
        <mesh filename="package://iri_wam_description/mesh/wam1.stl"/>
      </geometry>
      <material name="wam1-mat">
        <color rgba="0.75 0.75 0.75 1.0"/>
      </material>
    </visual>
    <collision>
      <origin rpy="0 0 0" xyz="0 0 0"/>
      <geometry name="wam1-geom">
        <mesh filename="package://iri_wam_description/mesh/wam1.stl"/>
      </geometry>
      <contact_coefficients kd="1.0" kp="1000.0" mu="0"/>
    </collision>
  </link>
  <link name="wam_fk/wam2">
    <inertial>
      <origin rpy="0 0 0" xyz="-0.00022300 -0.021392 0.013375"/>
      <mass value="4.8487"/>
      <inertia ixx="0.032413" ixy="-2e-06" ixz="-0.00014376" iyy="0.021649" iyz="-3.8e-06" izz="0.025027"/>
    </inertial>
    <visual>
      <origin rpy="0 0 0" xyz="0 0 0"/>
      <geometry name="wam2-geom">
        <mesh filename="package://iri_wam_description/mesh/wam2.stl"/>
      </geometry>
      <material name="wam2-mat">
        <color rgba="0.75 0.75 0.75 1.0"/>
      </material>
    </visual>
    <collision>
      <origin rpy="0 0 0" xyz="0 0 0"/>
      <geometry name="wam2-geom">
        <mesh filename="package://iri_wam_description/mesh/wam2.stl"/>
      </geometry>
      <contact_coefficients kd="1.0" kp="1000.0" mu="0"/>
    </collision>
  </link>
  <link name="wam_fk/wam3">
    <inertial>
      <origin rpy="0 0 0" xyz="-0.038757 0.21791 0.0000025"/>
      <mass value="1.7251"/>
      <inertia ixx="0.13858" ixy="-0.01689" ixz="6e-07" iyy="0.0057492" iyz="-7e-07" izz="0.14131"/>
    </inertial>
    <visual>
      <origin rpy="0 0 0" xyz="0 0 0"/>
      <geometry name="wam3-geom">
        <mesh filename="package://iri_wam_description/mesh/wam3.stl"/>
      </geometry>
      <material name="wam3-mat">
        <color rgba="0.75 0.75 0.75 1.0"/>
      </material>
    </visual>
    <collision>
      <origin rpy="0 0 0" xyz="0 0 0"/>
      <geometry name="wam3-geom">
        <mesh filename="package://iri_wam_description/mesh/wam3.stl"/>
      </geometry>
      <contact_coefficients kd="1.0" kp="1000.0" mu="0"/>
    </collision>
  </link>
  <link name="wam_fk/wam4">
    <inertial>
      <origin rpy="0 0 0" xyz="0.0062895 -0.0000001 0.11106"/>
      <mass value="2.0824"/>
      <inertia ixx="0.035752" ixy="1.4e-06" ixz="6.2e-06" iyy="0.03577" iyz="-2.9e-06" izz="0.0029213"/>
    </inertial>
    <visual>
      <origin rpy="0 0 0" xyz="0 0 0"/>
      <geometry name="wam4-geom">
        <mesh filename="package://iri_wam_description/mesh/wam4.stl"/>
      </geometry>
      <material name="wam4-mat">
        <color rgba="0.75 0.75 0.75 1.0"/>
      </material>
    </visual>
    <collision>
      <origin rpy="0 0 0" xyz="0 0 0"/>
      <geometry name="wam4-geom">
        <mesh filename="package://iri_wam_description/mesh/wam4.stl"/>
      </geometry>
      <contact_coefficients kd="1.0" kp="1000.0" mu="0"/>
    </collision>
  </link>
  <link name="wam_fk/wam5">
    <inertial>
      <origin rpy="0 0 0" xyz="0.000005 0.028375 0.00019020"/>
      <mass value="0.3067"/>
      <inertia ixx="0.00056797" ixy="4e-07" ixz="4e-10" iyy="0.00017238" iyz="-8e-08" izz="0.00059763"/>
    </inertial>
    <visual>
      <origin rpy="0 0 0" xyz="0 0 0"/>
      <geometry name="wam5-geom">
        <mesh filename="package://iri_wam_description/mesh/wam5.stl"/>
      </geometry>
      <material name="wam5-mat">
        <color rgba="0.75 0.75 0.75 1.0"/>
      </material>
    </visual>
    <collision>
      <origin rpy="0 0 0" xyz="0 0 0"/>
      <geometry name="wam5-geom">
        <mesh filename="package://iri_wam_description/mesh/wam5.stl"/>
      </geometry>
      <contact_coefficients kd="1.0" kp="1000.0" mu="0"/>
    </collision>
  </link>
  <link name="wam_fk/wam6">
    <inertial>
      <origin rpy="0 0 0" xyz="-0.000003 -0.014864 0.025633"/>
      <mass value="0.4278"/>
      <inertia ixx="0.00097981" ixy="2e-08" ixz="-5.3e-08" iyy="0.0005504" iyz="-0.00022533" izz="0.00060242"/>
    </inertial>
    <visual>
      <origin rpy="0 0 0" xyz="0 0 0"/>
      <geometry name="wam6-geom">
        <mesh filename="package://iri_wam_description/mesh/wam6.stl"/>
      </geometry>
      <material name="wam6-mat">
        <color rgba="0.75 0.75 0.75 1.0"/>
      </material>
    </visual>
    <collision>
      <origin rpy="0 0 0" xyz="0 0 0"/>
      <geometry name="wam6-geom">
        <mesh filename="package://iri_wam_description/mesh/wam6.stl"/>
      </geometry>
      <contact_coefficients kd="1.0" kp="1000.0" mu="0"/>
    </collision>
  </link>
  <link name="wam_fk/wam7">
    <inertial>
      <origin rpy="0 0 0" xyz="-0.00000001 -0.00018230 -0.28474 "/>
      <mass value="0.0557"/>
      <inertia ixx="0.0045368" ixy="-1e-11" ixz="1e-10" iyy="0.004537" iyz="2.8e-07" izz="4.2e-06"/>
    </inertial>
    <visual>
      <origin rpy="0 0 0" xyz="0 0 0"/>
      <geometry name="wam7-geom">
        <mesh filename="package://iri_wam_description/mesh/wam7.stl"/>
      </geometry>
      <material name="wam7-mat">
        <color rgba="0.75 0.75 0.75 1.0"/>
      </material>
    </visual>
    <collision>
      <origin rpy="0 0 0" xyz="0 0 0"/>
      <geometry name="wam7-geom">
        <mesh filename="package://iri_wam_description/mesh/wam7.stl"/>
      </geometry>
      <contact_coefficients kd="1.0" kp="1000.0" mu="0"/>
    </collision>
  </link>
  <!-- JOINTS  -->
  <joint name="j1" type="revolute">
    <parent link="wambase"/>
    <child link="wam_fk/wam1"/>
    <origin rpy="0 0 0" xyz="0.22 0.14 0.346"/>
    <limit effort="30" lower="-2.6" upper="2.6" velocity="2"/>
    <axis xyz="0 0 1"/>
  </joint>
  <joint name="j2" type="revolute">
    <parent link="wam_fk/wam1"/>
    <child link="wam_fk/wam2"/>
    <origin rpy="0 0 0" xyz="0 0 0"/>
    <limit effort="30" lower="-2.0" upper="2.0" velocity="2"/>
    <axis xyz="0 1 0"/>
  </joint>
  <joint name="j3" type="revolute">
    <parent link="wam_fk/wam2"/>
    <child link="wam_fk/wam3"/>
    <origin rpy="0 0 0" xyz="0.0 0.0 0.0"/>
    <limit effort="30" lower="-2.8" upper="2.8" velocity="2"/>
    <axis xyz="0 0 1"/>
  </joint>
  <joint name="j4" type="revolute">
    <parent link="wam_fk/wam3"/>
    <child link="wam_fk/wam4"/>
    <origin rpy="-1.5708 0 0" xyz="0.045 0 0.55"/>
    <limit effort="30" lower="-0.9" upper="3.1" velocity="2"/>
    <axis xyz="0 0 1"/>
  </joint>
  <joint name="j5" type="revolute">
    <parent link="wam_fk/wam4"/>
    <child link="wam_fk/wam5"/>
    <origin rpy="1.5708 0 0" xyz="-0.045 -0.3 0"/>
    <limit effort="30" lower="-4.8" upper="1.3" velocity="2"/>
    <axis xyz="0 0 1"/>
  </joint>
  <joint name="j6" type="revolute">
    <parent link="wam_fk/wam5"/>
    <child link="wam_fk/wam6"/>
    <origin rpy="-1.5708 0 0" xyz="0 0 0"/>
    <limit effort="30" lower="-1.6" upper="1.6" velocity="2"/>
    <axis xyz="0 0 1"/>
  </joint>
  <joint name="j7" type="revolute">
    <parent link="wam_fk/wam6"/>
    <child link="wam_fk/wam7"/>
    <origin rpy="1.5708 0 0" xyz="0 0 0"/>
    <limit effort="30" lower="-2.2" upper="2.2" velocity="2"/>
    <axis xyz="0 0 1"/>
  </joint>
  <!-- Transmission -->
  <transmission name="linkb_link0_trans" type="pr2_mechanism_model/SimpleTransmission">
    <actuator name="linkb_link0_motor"/>
    <joint name="j0"/>
    <mechanicalReduction>1</mechanicalReduction>
    <motorTorqueConstant>1</motorTorqueConstant>
    <!--  <pulsesPerRevolution>90000</pulsesPerRevolution>-->
  </transmission>
  <transmission name="link0_link1_trans" type="pr2_mechanism_model/SimpleTransmission">
    <actuator name="link0_link1_motor"/>
    <joint name="j1"/>
    <mechanicalReduction>1</mechanicalReduction>
    <motorTorqueConstant>1</motorTorqueConstant>
    <!--  <pulsesPerRevolution>90000</pulsesPerRevolution>-->
  </transmission>
  <transmission name="link1_link2_trans" type="pr2_mechanism_model/SimpleTransmission">
    <actuator name="link1_link2_motor"/>
    <joint name="j2"/>
    <mechanicalReduction>1</mechanicalReduction>
    <motorTorqueConstant>1</motorTorqueConstant>
    <!--  <pulsesPerRevolution>90000</pulsesPerRevolution>-->
  </transmission>
  <transmission name="link2_link3_trans" type="pr2_mechanism_model/SimpleTransmission">
    <actuator name="link2_link3_motor"/>
    <joint name="j3"/>
    <mechanicalReduction>1</mechanicalReduction>
    <motorTorqueConstant>1</motorTorqueConstant>
    <!--  <pulsesPerRevolution>90000</pulsesPerRevolution>-->
  </transmission>
  <transmission name="link3_link4_trans" type="pr2_mechanism_model/SimpleTransmission">
    <actuator name="link3_link4_motor"/>
    <joint name="j4"/>
    <mechanicalReduction>1</mechanicalReduction>
    <motorTorqueConstant>1</motorTorqueConstant>
    <!--  <pulsesPerRevolution>90000</pulsesPerRevolution>-->
  </transmission>
  <transmission name="link4_link5_trans" type="pr2_mechanism_model/SimpleTransmission">
    <actuator name="link4_link5_motor"/>
    <joint name="j5"/>
    <mechanicalReduction>1</mechanicalReduction>
    <motorTorqueConstant>1</motorTorqueConstant>
    <!--  <pulsesPerRevolution>90000</pulsesPerRevolution>-->
  </transmission>
  <transmission name="link5_link6_trans" type="pr2_mechanism_model/SimpleTransmission">
    <actuator name="link5_link6_motor"/>
    <joint name="j6"/>
    <mechanicalReduction>1</mechanicalReduction>
    <motorTorqueConstant>1</motorTorqueConstant>
    <!--  <pulsesPerRevolution>90000</pulsesPerRevolution>-->
  </transmission>
  <transmission name="link6_link7_trans" type="pr2_mechanism_model/SimpleTransmission">
    <actuator name="link6_link7_motor"/>
    <joint name="j7"/>
    <mechanicalReduction>1</mechanicalReduction>
    <motorTorqueConstant>1</motorTorqueConstant>
    <!--  <pulsesPerRevolution>90000</pulsesPerRevolution>-->
  </transmission>
  <!-- PLUGINS -->
  <gazebo>
    <controller:wam_gazebo name="wam_driver" plugin="libwam_gazebo.so">
      <alwaysOn>true</alwaysOn>
      <update>1000</update>
      <updateRate>1000.0</updateRate>
      <b1>wambase</b1>
      <b2>wam_fk/wam1</b2>
      <b3>wam_fk/wam2</b3>
      <b4>wam_fk/wam3</b4>
      <b5>wam_fk/wam4</b5>
      <b6>wam_fk/wam5</b6>
      <b7>wam_fk/wam6</b7>
      <b8>wam_fk/wam7</b8>
      <joint1>j1</joint1>
      <joint2>j2</joint2>
      <joint3>j3</joint3>
      <joint4>j4</joint4>
      <joint5>j5</joint5>
      <joint6>j6</joint6>
      <joint7>j7</joint7>
      <robotNamespace>/</robotNamespace>
    </controller:wam_gazebo>
  </gazebo>
</robot>
