<?xml version="1.0" ?>
<!-- =================================================================================== -->
<!-- |    This document was autogenerated by xacro from /home/irojas/ros/iri-ros-pkg/iri_wam/iri_wam_description/xacro/wam_sim.urdf.xacro | -->
<!-- |    EDITING THIS FILE BY HAND IS NOT RECOMMENDED                                 | -->
<!-- =================================================================================== -->
<robot name="iri_wam" xmlns:controller="http://playerstage.sourceforge.net/gazebo/xmlschema/#controller" xmlns:interface="http://playerstage.sourceforge.net/gazebo/xmlschema/#interface" xmlns:sensor="http://playerstage.sourceforge.net/gazebo/xmlschema/#sensor" xmlns:xacro="http://www.ros.org/wiki/xacro">
  <!-- LINKS   -->
  <link name="world"/>
  <link name="wambase">
    <inertial>
      <mass value="20"/>
      <origin rpy="0 0 0" xyz="0.175 0.14 0.08"/>
      <inertia ixx="1.0" ixy="0.0" ixz="0.0" iyy="1.0" iyz="0.0" izz="1.0"/>
    </inertial>
    <visual>
      <origin rpy="0 0 0" xyz="0 0 0"/>
      <geometry name="wambase_visual">
        <mesh filename="package://iri_wam_description/mesh/wambase.stl" scale="1.0 1.0 1.0"/>
      </geometry>
      <material name="LightGrey">
        <color rgba="0.75 0.75 0.75 1.0"/>
      </material>
    </visual>
    <collision>
      <origin rpy="0 0 0" xyz="0 0 0"/>
      <geometry name="wambase_collision">
        <mesh filename="package://iri_wam_description/mesh/wambase.stl" scale="1.0 1.0 1.0"/>
        <!--        <box size="0.35 0.28 0.16"/>-->
      </geometry>
      <contact_coefficients kd="1.0" kp="1000.0" mu="0"/>
    </collision>
  </link>
  <gazebo reference="wambase">
    <material>Gazebo/Grey</material>
    <selfCollide>true</selfCollide>
  </gazebo>
  <joint name="base_fix" type="fixed">
    <parent link="world"/>
    <child link="wambase"/>
  </joint>
  <link name="wam_fk/wam1">
    <inertial>
      <mass value="8.3936"/>
      <origin rpy="0 0 0" xyz="0.0 0.0 0.0"/>
      <inertia ixx="1.0" ixy="0.0" ixz="0.0" iyy="1.0" iyz="0.0" izz="1.0"/>
    </inertial>
    <visual>
      <origin rpy="0 0 0" xyz="0.0 0.0 0.0"/>
      <geometry name="wam_fk/wam1_visual">
        <mesh filename="package://iri_wam_description/mesh/wam1.stl" scale="1.0 1.0 1.0"/>
      </geometry>
      <material name="Grey">
        <color rgba="0.75 0.75 0.75 1.0"/>
      </material>
    </visual>
    <collision>
      <origin rpy="0 0 0" xyz="0.0 0.0 0.0"/>
      <geometry name="wam_fk/wam1_collision">
        <mesh filename="package://iri_wam_description/mesh/wam1.stl" scale="1.0 1.0 1.0"/>
        <!--                <box size="0.20 0.40 0.40"/>
-->
      </geometry>
      <contact_coefficients kd="1.0" kp="1000.0" mu="0"/>
    </collision>
  </link>
  <gazebo reference="wam_fk/wam1">
    <material>Gazebo/Grey</material>
    <selfCollide>true</selfCollide>
  </gazebo>
  <joint name="j1" type="revolute">
    <parent link="wambase"/>
    <child link="wam_fk/wam1"/>
    <origin rpy="0 0 0" xyz="0.22 0.14 0.346"/>
    <axis xyz="0 0 1"/>
    <limit effort="30" lower="-2.6" upper="2.6" velocity="2.0"/>
    <!--  <safety_controller k_velocity="0.5"/>-->
    <dynamics damping="100"/>
  </joint>
  <transmission name="wam_fk/wam1_transmission" type="pr2_mechanism_model/SimpleTransmission">
    <actuator name="wam_fk/wam1_rotation"/>
    <joint name="j1"/>
    <mechanicalReduction>1</mechanicalReduction>
    <motorTorqueConstant>1</motorTorqueConstant>
  </transmission>
  <link name="wam_fk/wam2">
    <inertial>
      <origin rpy="0 0 0" xyz="0 0 0"/>
      <mass value="4.8487"/>
      <inertia ixx="1.0" ixy="0.0" ixz="0.0" iyy="0.1" iyz="0.0" izz="0.1"/>
    </inertial>
    <visual>
      <origin rpy="0 0 0" xyz="0.0 0.0 0.0"/>
      <geometry name="wam_fk/wam2_visual">
        <mesh filename="package://iri_wam_description/mesh/wam2.stl" scale="1.0 1.0 1.0"/>
      </geometry>
      <material name="Grey">
        <color rgba="0.75 0.75 0.75 1.0"/>
      </material>
    </visual>
    <collision>
      <origin rpy="0 0 0" xyz="0.0 0.0 0.0"/>
      <geometry name="wam_fk/wam2_collision">
        <mesh filename="package://iri_wam_description/mesh/wam2.stl" scale="1.0 1.0 1.0"/>
        <!--                <box size="0.10 0.10 0.10"/> -->
      </geometry>
      <contact_coefficients kd="1.0" kp="1000.0" mu="0"/>
    </collision>
  </link>
  <gazebo reference="wam_fk/wam2">
    <material>Gazebo/Grey</material>
    <selfCollide>true</selfCollide>
  </gazebo>
  <joint name="j2" type="revolute">
    <parent link="wam_fk/wam1"/>
    <child link="wam_fk/wam2"/>
    <origin rpy="0 0 0" xyz="0.0 0.0 0.0"/>
    <axis xyz="0 1 0"/>
    <limit effort="30" lower="-2.0" upper="2.0" velocity="2.0"/>
    <!--<safety_controller k_velocity="0.5"/>-->
    <dynamics damping="100"/>
  </joint>
  <transmission name="wam_fk/wam2_transmission" type="pr2_mechanism_model/SimpleTransmission">
    <actuator name="wam_fk/wam2_rotation"/>
    <joint name="j2"/>
    <mechanicalReduction>1</mechanicalReduction>
    <motorTorqueConstant>1</motorTorqueConstant>
    <!--<pulsesPerRevolution>90000</pulsesPerRevolution>-->
  </transmission>
  <link name="wam_fk/wam3">
    <inertial>
      <mass value="1.7251"/>
      <origin rpy="0 0 0" xyz="0 0 0.225"/>
      <inertia ixx="1.0" ixy="0.0" ixz="0.0" iyy="0.1" iyz="0.0" izz="0.1"/>
    </inertial>
    <visual>
      <origin rpy="0 0 0" xyz="0.0 0.0 0.0"/>
      <geometry name="wam_fk/wam3_visual">
        <mesh filename="package://iri_wam_description/mesh/wam3.stl" scale="1.0 1.0 1.0"/>
      </geometry>
      <material name="Grey">
        <color rgba="0.75 0.75 0.75 1.0"/>
      </material>
    </visual>
    <collision>
      <origin rpy="0 0 0" xyz="0.0 0.0 0.0"/>
      <geometry name="wam_fk/wam3_collision">
        <mesh filename="package://iri_wam_description/mesh/wam3.stl" scale="1.0 1.0 1.0"/>
        <!--                <box size="0.10 0.10 0.10"/> -->
      </geometry>
      <contact_coefficients kd="1.0" kp="1000.0" mu="0"/>
    </collision>
  </link>
  <gazebo reference="wam_fk/wam3">
    <material>Gazebo/Grey</material>
    <selfCollide>true</selfCollide>
  </gazebo>
  <joint name="j3" type="revolute">
    <parent link="wam_fk/wam2"/>
    <child link="wam_fk/wam3"/>
    <origin rpy="0 0 0" xyz="0.0 0.0 0.0"/>
    <axis xyz="0 0 1"/>
    <limit effort="30" lower="-2.8" upper="2.8" velocity="2.0"/>
    <!--  <safety_controller k_velocity="0.5"/>-->
    <dynamics damping="100"/>
  </joint>
  <transmission name="wam_fk/wam3_transmission" type="pr2_mechanism_model/SimpleTransmission">
    <actuator name="wam_fk/wam3_rotation"/>
    <joint name="j3"/>
    <mechanicalReduction>1</mechanicalReduction>
    <motorTorqueConstant>1</motorTorqueConstant>
    <!-- <pulsesPerRevolution>90000</pulsesPerRevolution>-->
  </transmission>
  <link name="wam_fk/wam4">
    <inertial>
      <mass value="2.0824"/>
      <origin rpy="0 0 0" xyz="-0.045 -0.15 0"/>
      <inertia ixx="1.0" ixy="0.0" ixz="0.0" iyy="0.1" iyz="0.0" izz="0.1"/>
    </inertial>
    <visual>
      <origin rpy="0 0 0" xyz="0.0 0.0 0.0"/>
      <geometry name="wam_fk/wam4_visual">
        <mesh filename="package://iri_wam_description/mesh/wam4.stl" scale="1.0 1.0 1.0"/>
      </geometry>
      <material name="Grey">
        <color rgba="0.75 0.75 0.75 1.0"/>
      </material>
    </visual>
    <collision>
      <origin rpy="0 0 0" xyz="0.0 0.0 0.0"/>
      <geometry name="wam_fk/wam4_collision">
        <mesh filename="package://iri_wam_description/mesh/wam4.stl" scale="1.0 1.0 1.0"/>
        <!--                <box size="0.10 0.10 0.10"/> -->
      </geometry>
      <contact_coefficients kd="1.0" kp="1000.0" mu="0"/>
    </collision>
  </link>
  <gazebo reference="wam_fk/wam4">
    <material>Gazebo/Grey</material>
    <selfCollide>true</selfCollide>
  </gazebo>
  <joint name="j4" type="revolute">
    <parent link="wam_fk/wam3"/>
    <child link="wam_fk/wam4"/>
    <origin rpy="-1.57079632679 0 0" xyz="0.045 0.0 0.55"/>
    <axis xyz="0 0 1"/>
    <limit effort="35" lower="-0.9" upper="2.8" velocity="2.0"/>
    <!--  <safety_controller k_velocity="0.5"/>-->
    <dynamics damping="100"/>
  </joint>
  <transmission name="wam_fk/wam4_transmission" type="pr2_mechanism_model/SimpleTransmission">
    <actuator name="wam_fk/wam4_rotation"/>
    <joint name="j4"/>
    <mechanicalReduction>1</mechanicalReduction>
    <motorTorqueConstant>1</motorTorqueConstant>
    <!--<pulsesPerRevolution>90000</pulsesPerRevolution>-->
  </transmission>
  <link name="wam_fk/wam5">
    <inertial>
      <origin rpy="0 0 0" xyz="0 0 0"/>
      <mass value="0.3067"/>
      <inertia ixx="1.0" ixy="0.0" ixz="0.0" iyy="0.1" iyz="0.0" izz="0.1"/>
    </inertial>
    <visual>
      <origin rpy="0 0 0" xyz="0.0 0.0 0.0"/>
      <geometry name="wam_fk/wam5_visual">
        <mesh filename="package://iri_wam_description/mesh/wam5.stl" scale="1.0 1.0 1.0"/>
      </geometry>
      <material name="Grey">
        <color rgba="0.75 0.75 0.75 1.0"/>
      </material>
    </visual>
    <collision>
      <origin rpy="0 0 0" xyz="0.0 0.0 0.0"/>
      <geometry name="wam_fk/wam5_collision">
        <mesh filename="package://iri_wam_description/mesh/wam5.stl" scale="1.0 1.0 1.0"/>
        <!--                <box size="0.10 0.10 0.10"/> -->
      </geometry>
      <contact_coefficients kd="1.0" kp="1000.0" mu="0"/>
    </collision>
  </link>
  <gazebo reference="wam_fk/wam5">
    <material>Gazebo/Grey</material>
    <selfCollide>true</selfCollide>
  </gazebo>
  <joint name="j5" type="revolute">
    <parent link="wam_fk/wam4"/>
    <child link="wam_fk/wam5"/>
    <origin rpy="1.57079632679 0 0" xyz="-0.045 -0.3 0.0"/>
    <axis xyz="0 0 1"/>
    <limit effort="30" lower="-4.8" upper="1.3" velocity="2.0"/>
    <!--  <safety_controller k_velocity="0.5"/>-->
    <dynamics damping="100"/>
  </joint>
  <transmission name="wam_fk/wam5_transmission" type="pr2_mechanism_model/SimpleTransmission">
    <actuator name="wam_fk/wam5_rotation"/>
    <joint name="j5"/>
    <mechanicalReduction>1</mechanicalReduction>
    <motorTorqueConstant>1</motorTorqueConstant>
    <!--  <pulsesPerRevolution>90000</pulsesPerRevolution>-->
  </transmission>
  <link name="wam_fk/wam6">
    <inertial>
      <origin rpy="0 0 0" xyz="0 0 0"/>
      <mass value="0.4278"/>
      <inertia ixx="1.0" ixy="0.0" ixz="0.0" iyy="0.1" iyz="0.0" izz="0.1"/>
    </inertial>
    <visual>
      <origin rpy="0 0 0" xyz="0.0 0.0 0.0"/>
      <geometry name="wam_fk/wam6_visual">
        <mesh filename="package://iri_wam_description/mesh/wam6.stl" scale="1.0 1.0 1.0"/>
      </geometry>
      <material name="Grey">
        <color rgba="0.75 0.75 0.75 1.0"/>
      </material>
    </visual>
    <collision>
      <origin rpy="0 0 0" xyz="0.0 0.0 0.0"/>
      <geometry name="wam_fk/wam6_collision">
        <mesh filename="package://iri_wam_description/mesh/wam6.stl" scale="1.0 1.0 1.0"/>
        <!--                <box size="0.10 0.10 0.10"/> -->
      </geometry>
      <contact_coefficients kd="1.0" kp="1000.0" mu="0"/>
    </collision>
  </link>
  <gazebo reference="wam_fk/wam6">
    <material>Gazebo/Grey</material>
    <selfCollide>true</selfCollide>
  </gazebo>
  <joint name="j6" type="revolute">
    <parent link="wam_fk/wam5"/>
    <child link="wam_fk/wam6"/>
    <origin rpy="-1.57079632679 0 0" xyz="0.0 0.0 0.0"/>
    <axis xyz="0 0 1"/>
    <limit effort="30" lower="-1.6" upper="1.6" velocity="2.0"/>
    <!--  <safety_controller k_velocity="0.5"/>-->
    <dynamics damping="100"/>
  </joint>
  <transmission name="wam_fk/wam6_transmission" type="pr2_mechanism_model/SimpleTransmission">
    <actuator name="wam_fk/wam6_rotation"/>
    <joint name="j6"/>
    <mechanicalReduction>1</mechanicalReduction>
    <motorTorqueConstant>1</motorTorqueConstant>
    <!--  <pulsesPerRevolution>90000</pulsesPerRevolution>-->
  </transmission>
  <link name="wam_fk/wam7">
    <inertial>
      <origin rpy="0 0 0" xyz="0 0 0"/>
      <mass value="0.0557"/>
      <inertia ixx="1.0" ixy="0.0" ixz="0.0" iyy="0.1" iyz="0.0" izz="0.1"/>
    </inertial>
    <visual>
      <origin rpy="0 0 0" xyz="0.0 0.0 0.0"/>
      <geometry name="wam_fk/wam7_visual">
        <mesh filename="package://iri_wam_description/mesh/wam7.stl" scale="1.0 1.0 1.0"/>
      </geometry>
      <material name="Grey">
        <color rgba="0.75 0.75 0.75 1.0"/>
      </material>
    </visual>
    <collision>
      <origin rpy="0 0 0" xyz="0.0 0.0 0.0"/>
      <geometry name="wam_fk/wam7_collision">
        <mesh filename="package://iri_wam_description/mesh/wam7.stl" scale="1.0 1.0 1.0"/>
        <!--                <box size="0.10 0.10 0.10"/> -->
      </geometry>
      <contact_coefficients kd="1.0" kp="1000.0" mu="0"/>
    </collision>
  </link>
  <gazebo reference="wam_fk/wam7">
    <material>Gazebo/Grey</material>
    <selfCollide>true</selfCollide>
  </gazebo>
  <joint name="j7" type="revolute">
    <parent link="wam_fk/wam6"/>
    <child link="wam_fk/wam7"/>
    <origin rpy="1.57079632679 0 0" xyz="0.0 0.0 0.0"/>
    <axis xyz="0 0 1"/>
    <limit effort="30" lower="-2.2" upper="2.2" velocity="2.0"/>
    <!--  <safety_controller k_velocity="0.5"/>-->
    <dynamics damping="100"/>
  </joint>
  <transmission name="wam_fk/wam7_transmission" type="pr2_mechanism_model/SimpleTransmission">
    <actuator name="wam_fk/wam7_rotation"/>
    <joint name="j7"/>
    <mechanicalReduction>1</mechanicalReduction>
    <motorTorqueConstant>1</motorTorqueConstant>
    <!--<pulsesPerRevolution>90000</pulsesPerRevolution>-->
  </transmission>
  <!-- PLUGINS -->
  <gazebo>
    <!--<controller:wam_gazebo name="wam_driver" plugin="libwam_gazebo.so">
		<alwaysOn>true</alwaysOn>
		<update>1000</update>
		<updateRate>1000.0</updateRate>
		<b1>wambase</b1>
		<b2>wam_fk/wam1</b2>
		<b3>wam_fk/wam2</b3>
		<b4>wam_fk/wam3</b4>
		<b5>wam_fk/wam4</b5>
		<b6>wam_fk/wam5</b6>
		<b7>wam_fk/wam6</b7>
		<b8>wam_fk/wam7</b8>		
    	<joint1>j1</joint1>
		<joint2>j2</joint2>
		<joint3>j3</joint3>
		<joint4>j4</joint4>
		<joint5>j5</joint5>
		<joint6>j6</joint6>
		<joint7>j7</joint7>	
		<robotNamespace>/</robotNamespace>
	</controller:wam_gazebo>
	-->
    <controller:gazebo_ros_controller_manager name="gazebo_ros_controller_manager" plugin="libgazebo_ros_controller_manager.so">
      <alwaysOn>true</alwaysOn>
      <update>1000</update>
      <updateRate>1000.0</updateRate>
      <robotParam>robot_description</robotParam>
      <robotNamespace>/</robotNamespace>
    </controller:gazebo_ros_controller_manager>
  </gazebo>
</robot>
