<?xml version="1.0"?>
<robot name="segway_head">
  <link name="neck1">
    <visual>
      <geometry>
        <box size="0.061 0.04 0.04"/>
      </geometry>
    </visual>
  </link>

  <link name="neck2">
    <visual>
      <geometry>
        <box size="0.061 0.04 0.04"/>
      </geometry>
      <origin rpy="0 0.0 3.1415927" xyz="0.04 0 0"/>
    </visual>
  </link>

  <link name="neck3">
    <visual>
      <geometry>
        <box size="0.061 0.04 0.04"/>
      </geometry>
      <origin rpy="1.5707963 0 0" xyz="-0.015 0 0.045"/>
    </visual>
  </link>

  <link name="head">
    <visual>
      <geometry>
        <box size="0.1 0.1 0.1"/>
      </geometry>
      <origin rpy="0 0 0" xyz="0 0 0.08"/>
    </visual>
  </link>

  <joint name="pan" type="revolute">
    <parent link="neck1"/>
    <child link="neck2"/>
    <origin rpy="-2.62 -1.5707963 0" xyz="0.02 0 0.02"/>
    <limit effort="1000.0" lower="0.0" upper="5.24" velocity="0.5"/>
  </joint>

  <joint name="side" type="revolute">
    <parent link="neck2"/>
    <child link="neck3"/>
    <origin rpy="-2.62 1.5707963 0" xyz="0.055 0 0"/>
    <limit effort="1000.0" lower="0.0" upper="5.24" velocity="0.5"/>
  </joint>

  <joint name="tilt" type="revolute">
    <parent link="neck3"/>
    <child link="head"/>
    <origin rpy="-2.62 0 1.5707963" xyz="0 0 0.045"/>
    <limit effort="1000.0" lower="0.0" upper="5.24" velocity="0.5"/>
  </joint>
</robot>

